[ERROR][log.log_response()] Internal Server Error: /
Traceback (most recent call last):
  File "/usr/local/lib/python3.9/site-packages/django/core/handlers/exception.py", line 47, in inner
    response = get_response(request)
  File "/usr/local/lib/python3.9/site-packages/django/core/handlers/base.py", line 181, in _get_response
    response = wrapped_callback(request, *callback_args, **callback_kwargs)
  File "/workspaces/django/apps/book/views.py", line 15, in home
    raise Exception("test")
Exception: test
[ERROR][basehttp.log_message()] "GET / HTTP/1.1" 500 63607
[ERROR][log.log_response()] Internal Server Error: /manage/book/1/
Traceback (most recent call last):
  File "/usr/local/lib/python3.9/site-packages/django/core/handlers/exception.py", line 47, in inner
    response = get_response(request)
  File "/usr/local/lib/python3.9/site-packages/django/core/handlers/base.py", line 181, in _get_response
    response = wrapped_callback(request, *callback_args, **callback_kwargs)
  File "/usr/local/lib/python3.9/site-packages/django/contrib/auth/decorators.py", line 21, in _wrapped_view
    return view_func(request, *args, **kwargs)
  File "/workspaces/django/apps/management/views.py", line 28, in management_book_edit
    return redirect('管理画面のURLまたは適切な場所へのリダイレクト')
  File "/usr/local/lib/python3.9/site-packages/django/shortcuts.py", line 41, in redirect
    return redirect_class(resolve_url(to, *args, **kwargs))
  File "/usr/local/lib/python3.9/site-packages/django/shortcuts.py", line 130, in resolve_url
    return reverse(to, args=args, kwargs=kwargs)
  File "/usr/local/lib/python3.9/site-packages/django/urls/base.py", line 86, in reverse
    return resolver._reverse_with_prefix(view, prefix, *args, **kwargs)
  File "/usr/local/lib/python3.9/site-packages/django/urls/resolvers.py", line 698, in _reverse_with_prefix
    raise NoReverseMatch(msg)
django.urls.exceptions.NoReverseMatch: Reverse for '管理画面のURLまたは適切な場所へのリダイレクト' not found. '管理画面のURLまたは適切な場所へのリダイレクト' is not a valid view function or pattern name.
[ERROR][basehttp.log_message()] "POST /manage/book/1/ HTTP/1.1" 500 92068
[ERROR][log.log_response()] Internal Server Error: /manage/books/
Traceback (most recent call last):
  File "/usr/local/lib/python3.9/site-packages/django/core/handlers/exception.py", line 47, in inner
    response = get_response(request)
  File "/usr/local/lib/python3.9/site-packages/django/core/handlers/base.py", line 181, in _get_response
    response = wrapped_callback(request, *callback_args, **callback_kwargs)
  File "/usr/local/lib/python3.9/site-packages/django/contrib/auth/decorators.py", line 21, in _wrapped_view
    return view_func(request, *args, **kwargs)
  File "/workspaces/django/apps/management/views.py", line 19, in management_books
    return render(request, "pages/manage-books.html", context)
  File "/usr/local/lib/python3.9/site-packages/django/shortcuts.py", line 19, in render
    content = loader.render_to_string(template_name, context, request, using=using)
  File "/usr/local/lib/python3.9/site-packages/django/template/loader.py", line 62, in render_to_string
    return template.render(context, request)
  File "/usr/local/lib/python3.9/site-packages/django/template/backends/django.py", line 61, in render
    return self.template.render(context)
  File "/usr/local/lib/python3.9/site-packages/django/template/base.py", line 170, in render
    return self._render(context)
  File "/usr/local/lib/python3.9/site-packages/django/template/base.py", line 162, in _render
    return self.nodelist.render(context)
  File "/usr/local/lib/python3.9/site-packages/django/template/base.py", line 938, in render
    bit = node.render_annotated(context)
  File "/usr/local/lib/python3.9/site-packages/django/template/base.py", line 905, in render_annotated
    return self.render(context)
  File "/usr/local/lib/python3.9/site-packages/django/template/loader_tags.py", line 150, in render
    return compiled_parent._render(context)
  File "/usr/local/lib/python3.9/site-packages/django/template/base.py", line 162, in _render
    return self.nodelist.render(context)
  File "/usr/local/lib/python3.9/site-packages/django/template/base.py", line 938, in render
    bit = node.render_annotated(context)
  File "/usr/local/lib/python3.9/site-packages/django/template/base.py", line 905, in render_annotated
    return self.render(context)
  File "/usr/local/lib/python3.9/site-packages/django/template/loader_tags.py", line 62, in render
    result = block.nodelist.render(context)
  File "/usr/local/lib/python3.9/site-packages/django/template/base.py", line 938, in render
    bit = node.render_annotated(context)
  File "/usr/local/lib/python3.9/site-packages/django/template/base.py", line 905, in render_annotated
    return self.render(context)
  File "/usr/local/lib/python3.9/site-packages/django/template/defaulttags.py", line 449, in render
    url = reverse(view_name, args=args, kwargs=kwargs, current_app=current_app)
  File "/usr/local/lib/python3.9/site-packages/django/urls/base.py", line 86, in reverse
    return resolver._reverse_with_prefix(view, prefix, *args, **kwargs)
  File "/usr/local/lib/python3.9/site-packages/django/urls/resolvers.py", line 698, in _reverse_with_prefix
    raise NoReverseMatch(msg)
django.urls.exceptions.NoReverseMatch: Reverse for 'management-dashboard' not found. 'management-dashboard' is not a valid view function or pattern name.
[ERROR][basehttp.log_message()] "GET /manage/books/ HTTP/1.1" 500 168594
[ERROR][log.log_response()] Internal Server Error: /manage/books/
Traceback (most recent call last):
  File "/usr/local/lib/python3.9/site-packages/django/core/handlers/exception.py", line 47, in inner
    response = get_response(request)
  File "/usr/local/lib/python3.9/site-packages/django/core/handlers/base.py", line 181, in _get_response
    response = wrapped_callback(request, *callback_args, **callback_kwargs)
  File "/usr/local/lib/python3.9/site-packages/django/contrib/auth/decorators.py", line 21, in _wrapped_view
    return view_func(request, *args, **kwargs)
  File "/workspaces/django/apps/management/views.py", line 19, in management_books
    return render(request, "pages/manage-books.html", context)
  File "/usr/local/lib/python3.9/site-packages/django/shortcuts.py", line 19, in render
    content = loader.render_to_string(template_name, context, request, using=using)
  File "/usr/local/lib/python3.9/site-packages/django/template/loader.py", line 62, in render_to_string
    return template.render(context, request)
  File "/usr/local/lib/python3.9/site-packages/django/template/backends/django.py", line 61, in render
    return self.template.render(context)
  File "/usr/local/lib/python3.9/site-packages/django/template/base.py", line 170, in render
    return self._render(context)
  File "/usr/local/lib/python3.9/site-packages/django/template/base.py", line 162, in _render
    return self.nodelist.render(context)
  File "/usr/local/lib/python3.9/site-packages/django/template/base.py", line 938, in render
    bit = node.render_annotated(context)
  File "/usr/local/lib/python3.9/site-packages/django/template/base.py", line 905, in render_annotated
    return self.render(context)
  File "/usr/local/lib/python3.9/site-packages/django/template/loader_tags.py", line 150, in render
    return compiled_parent._render(context)
  File "/usr/local/lib/python3.9/site-packages/django/template/base.py", line 162, in _render
    return self.nodelist.render(context)
  File "/usr/local/lib/python3.9/site-packages/django/template/base.py", line 938, in render
    bit = node.render_annotated(context)
  File "/usr/local/lib/python3.9/site-packages/django/template/base.py", line 905, in render_annotated
    return self.render(context)
  File "/usr/local/lib/python3.9/site-packages/django/template/loader_tags.py", line 62, in render
    result = block.nodelist.render(context)
  File "/usr/local/lib/python3.9/site-packages/django/template/base.py", line 938, in render
    bit = node.render_annotated(context)
  File "/usr/local/lib/python3.9/site-packages/django/template/base.py", line 905, in render_annotated
    return self.render(context)
  File "/usr/local/lib/python3.9/site-packages/django/template/defaulttags.py", line 449, in render
    url = reverse(view_name, args=args, kwargs=kwargs, current_app=current_app)
  File "/usr/local/lib/python3.9/site-packages/django/urls/base.py", line 86, in reverse
    return resolver._reverse_with_prefix(view, prefix, *args, **kwargs)
  File "/usr/local/lib/python3.9/site-packages/django/urls/resolvers.py", line 698, in _reverse_with_prefix
    raise NoReverseMatch(msg)
django.urls.exceptions.NoReverseMatch: Reverse for 'manage-dashboard' not found. 'manage-dashboard' is not a valid view function or pattern name.
[ERROR][basehttp.log_message()] "GET /manage/books/ HTTP/1.1" 500 168390
[ERROR][log.log_response()] Internal Server Error: /selection/11b0a576-5788-4add-8e80-9a8284635f53/
Traceback (most recent call last):
  File "/usr/local/lib/python3.9/site-packages/django/core/handlers/exception.py", line 47, in inner
    response = get_response(request)
  File "/usr/local/lib/python3.9/site-packages/django/core/handlers/base.py", line 181, in _get_response
    response = wrapped_callback(request, *callback_args, **callback_kwargs)
  File "/workspaces/django/apps/selection/views.py", line 103, in selection_detail
    context = usecase.execute(selection_id, request.user)
  File "/workspaces/django/config/application/usecases.py", line 24, in execute
    raise e
  File "/workspaces/django/config/application/usecases.py", line 12, in execute
    result = self.run(*args, **kwargs)
  File "/workspaces/django/apps/selection/application/usecases.py", line 46, in run
    is_liked = BookSelectionLike.objects.filter(user=user, selection=selection).exists()
  File "/usr/local/lib/python3.9/site-packages/django/db/models/manager.py", line 85, in manager_method
    return getattr(self.get_queryset(), name)(*args, **kwargs)
  File "/usr/local/lib/python3.9/site-packages/django/db/models/query.py", line 941, in filter
    return self._filter_or_exclude(False, args, kwargs)
  File "/usr/local/lib/python3.9/site-packages/django/db/models/query.py", line 961, in _filter_or_exclude
    clone._filter_or_exclude_inplace(negate, args, kwargs)
  File "/usr/local/lib/python3.9/site-packages/django/db/models/query.py", line 968, in _filter_or_exclude_inplace
    self._query.add_q(Q(*args, **kwargs))
  File "/usr/local/lib/python3.9/site-packages/django/db/models/sql/query.py", line 1393, in add_q
    clause, _ = self._add_q(q_object, self.used_aliases)
  File "/usr/local/lib/python3.9/site-packages/django/db/models/sql/query.py", line 1412, in _add_q
    child_clause, needed_inner = self.build_filter(
  File "/usr/local/lib/python3.9/site-packages/django/db/models/sql/query.py", line 1320, in build_filter
    self.check_related_objects(join_info.final_field, value, join_info.opts)
  File "/usr/local/lib/python3.9/site-packages/django/db/models/sql/query.py", line 1149, in check_related_objects
    for v in value:
  File "/usr/local/lib/python3.9/site-packages/django/utils/functional.py", line 247, in inner
    return func(self._wrapped, *args)
TypeError: 'AnonymousUser' object is not iterable
[ERROR][basehttp.log_message()] "GET /selection/11b0a576-5788-4add-8e80-9a8284635f53/ HTTP/1.1" 500 123760
[ERROR][log.log_response()] Internal Server Error: /manage/search-history/
Traceback (most recent call last):
  File "/usr/local/lib/python3.9/site-packages/django/template/base.py", line 470, in parse
    compile_func = self.tags[command]
KeyError: 'endblock'

During handling of the above exception, another exception occurred:

Traceback (most recent call last):
  File "/usr/local/lib/python3.9/site-packages/django/core/handlers/exception.py", line 47, in inner
    response = get_response(request)
  File "/usr/local/lib/python3.9/site-packages/django/core/handlers/base.py", line 181, in _get_response
    response = wrapped_callback(request, *callback_args, **callback_kwargs)
  File "/usr/local/lib/python3.9/site-packages/django/contrib/auth/decorators.py", line 21, in _wrapped_view
    return view_func(request, *args, **kwargs)
  File "/workspaces/django/apps/management/views.py", line 55, in management_search_history
    return render(request, "pages/manage-search-history.html", context)
  File "/usr/local/lib/python3.9/site-packages/django/shortcuts.py", line 19, in render
    content = loader.render_to_string(template_name, context, request, using=using)
  File "/usr/local/lib/python3.9/site-packages/django/template/loader.py", line 61, in render_to_string
    template = get_template(template_name, using=using)
  File "/usr/local/lib/python3.9/site-packages/django/template/loader.py", line 15, in get_template
    return engine.get_template(template_name)
  File "/usr/local/lib/python3.9/site-packages/django/template/backends/django.py", line 34, in get_template
    return Template(self.engine.get_template(template_name), self)
  File "/usr/local/lib/python3.9/site-packages/django/template/engine.py", line 143, in get_template
    template, origin = self.find_template(template_name)
  File "/usr/local/lib/python3.9/site-packages/django/template/engine.py", line 125, in find_template
    template = loader.get_template(name, skip=skip)
  File "/usr/local/lib/python3.9/site-packages/django/template/loaders/base.py", line 29, in get_template
    return Template(
  File "/usr/local/lib/python3.9/site-packages/django/template/base.py", line 155, in __init__
    self.nodelist = self.compile_nodelist()
  File "/usr/local/lib/python3.9/site-packages/django/template/base.py", line 193, in compile_nodelist
    return parser.parse()
  File "/usr/local/lib/python3.9/site-packages/django/template/base.py", line 478, in parse
    raise self.error(token, e)
  File "/usr/local/lib/python3.9/site-packages/django/template/base.py", line 476, in parse
    compiled_result = compile_func(self, token)
  File "/usr/local/lib/python3.9/site-packages/django/template/loader_tags.py", line 278, in do_extends
    nodelist = parser.parse()
  File "/usr/local/lib/python3.9/site-packages/django/template/base.py", line 472, in parse
    self.invalid_block_tag(token, command, parse_until)
  File "/usr/local/lib/python3.9/site-packages/django/template/base.py", line 531, in invalid_block_tag
    raise self.error(
django.template.exceptions.TemplateSyntaxError: Invalid block tag on line 16: 'endblock'. Did you forget to register or load this tag?
[ERROR][basehttp.log_message()] "GET /manage/search-history/ HTTP/1.1" 500 149700
[ERROR][log.log_response()] Internal Server Error: /detail/10/
Traceback (most recent call last):
  File "/usr/local/lib/python3.9/site-packages/django/core/handlers/exception.py", line 47, in inner
    response = get_response(request)
  File "/usr/local/lib/python3.9/site-packages/django/core/handlers/base.py", line 181, in _get_response
    response = wrapped_callback(request, *callback_args, **callback_kwargs)
  File "/workspaces/django/apps/book/views.py", line 33, in book_detail_page
    return render(request, "pages/book_detail.html", context)
  File "/usr/local/lib/python3.9/site-packages/django/shortcuts.py", line 19, in render
    content = loader.render_to_string(template_name, context, request, using=using)
  File "/usr/local/lib/python3.9/site-packages/django/template/loader.py", line 62, in render_to_string
    return template.render(context, request)
  File "/usr/local/lib/python3.9/site-packages/django/template/backends/django.py", line 61, in render
    return self.template.render(context)
  File "/usr/local/lib/python3.9/site-packages/django/template/base.py", line 170, in render
    return self._render(context)
  File "/usr/local/lib/python3.9/site-packages/django/template/base.py", line 162, in _render
    return self.nodelist.render(context)
  File "/usr/local/lib/python3.9/site-packages/django/template/base.py", line 938, in render
    bit = node.render_annotated(context)
  File "/usr/local/lib/python3.9/site-packages/django/template/base.py", line 905, in render_annotated
    return self.render(context)
  File "/usr/local/lib/python3.9/site-packages/django/template/loader_tags.py", line 150, in render
    return compiled_parent._render(context)
  File "/usr/local/lib/python3.9/site-packages/django/template/base.py", line 162, in _render
    return self.nodelist.render(context)
  File "/usr/local/lib/python3.9/site-packages/django/template/base.py", line 938, in render
    bit = node.render_annotated(context)
  File "/usr/local/lib/python3.9/site-packages/django/template/base.py", line 905, in render_annotated
    return self.render(context)
  File "/usr/local/lib/python3.9/site-packages/django/template/loader_tags.py", line 62, in render
    result = block.nodelist.render(context)
  File "/usr/local/lib/python3.9/site-packages/django/template/base.py", line 938, in render
    bit = node.render_annotated(context)
  File "/usr/local/lib/python3.9/site-packages/django/template/base.py", line 905, in render_annotated
    return self.render(context)
  File "/usr/local/lib/python3.9/site-packages/django/template/library.py", line 192, in render
    output = self.func(*resolved_args, **resolved_kwargs)
  File "/workspaces/django/apps/review/templatetags/review_tags.py", line 15, in review_list
    return mark_safe(render_to_string("components/_review_list.html", context))
  File "/usr/local/lib/python3.9/site-packages/django/template/loader.py", line 61, in render_to_string
    template = get_template(template_name, using=using)
  File "/usr/local/lib/python3.9/site-packages/django/template/loader.py", line 15, in get_template
    return engine.get_template(template_name)
  File "/usr/local/lib/python3.9/site-packages/django/template/backends/django.py", line 34, in get_template
    return Template(self.engine.get_template(template_name), self)
  File "/usr/local/lib/python3.9/site-packages/django/template/engine.py", line 143, in get_template
    template, origin = self.find_template(template_name)
  File "/usr/local/lib/python3.9/site-packages/django/template/engine.py", line 125, in find_template
    template = loader.get_template(name, skip=skip)
  File "/usr/local/lib/python3.9/site-packages/django/template/loaders/base.py", line 29, in get_template
    return Template(
  File "/usr/local/lib/python3.9/site-packages/django/template/base.py", line 155, in __init__
    self.nodelist = self.compile_nodelist()
  File "/usr/local/lib/python3.9/site-packages/django/template/base.py", line 193, in compile_nodelist
    return parser.parse()
  File "/usr/local/lib/python3.9/site-packages/django/template/base.py", line 478, in parse
    raise self.error(token, e)
  File "/usr/local/lib/python3.9/site-packages/django/template/base.py", line 476, in parse
    compiled_result = compile_func(self, token)
  File "/usr/local/lib/python3.9/site-packages/django/template/defaulttags.py", line 817, in do_for
    nodelist_loop = parser.parse(('empty', 'endfor',))
  File "/usr/local/lib/python3.9/site-packages/django/template/base.py", line 449, in parse
    raise self.error(token, e)
  File "/usr/local/lib/python3.9/site-packages/django/template/base.py", line 447, in parse
    filter_expression = self.compile_filter(token.contents)
  File "/usr/local/lib/python3.9/site-packages/django/template/base.py", line 563, in compile_filter
    return FilterExpression(token, self)
  File "/usr/local/lib/python3.9/site-packages/django/template/base.py", line 633, in __init__
    raise TemplateSyntaxError("Could not parse some characters: "
django.template.exceptions.TemplateSyntaxError: Could not parse some characters: not| user.is_authenticated||yesno:"cursor-pointer"
[ERROR][basehttp.log_message()] "GET /detail/10/ HTTP/1.1" 500 258618
[ERROR][log.log_response()] Internal Server Error: /selection/11b0a576-5788-4add-8e80-9a8284635f53/
Traceback (most recent call last):
  File "/workspaces/django/apps/selection/domain/services.py", line 31, in get_selection_by_id
    return BookSelection.objects.get(id=selection_id)
  File "/usr/local/lib/python3.9/site-packages/django/db/models/manager.py", line 85, in manager_method
    return getattr(self.get_queryset(), name)(*args, **kwargs)
  File "/usr/local/lib/python3.9/site-packages/django/db/models/query.py", line 435, in get
    raise self.model.DoesNotExist(
apps.selection.models.BookSelection.DoesNotExist: BookSelection matching query does not exist.

During handling of the above exception, another exception occurred:

Traceback (most recent call last):
  File "/usr/local/lib/python3.9/site-packages/django/core/handlers/exception.py", line 47, in inner
    response = get_response(request)
  File "/usr/local/lib/python3.9/site-packages/django/core/handlers/base.py", line 181, in _get_response
    response = wrapped_callback(request, *callback_args, **callback_kwargs)
  File "/workspaces/django/apps/selection/views.py", line 103, in selection_detail
    context = usecase.execute(selection_id, request.user)
  File "/workspaces/django/config/application/usecases.py", line 24, in execute
    raise e
  File "/workspaces/django/config/application/usecases.py", line 12, in execute
    result = self.run(*args, **kwargs)
  File "/workspaces/django/apps/selection/application/usecases.py", line 45, in run
    selection = self.book_selection_service.get_selection_by_id(selection_id)
  File "/workspaces/django/apps/selection/domain/services.py", line 33, in get_selection_by_id
    raise ApplicationException("セレクションが存在しません。")
  File "/workspaces/django/config/exceptions.py", line 6, in __init__
    for field_errors in errors.values():
AttributeError: 'str' object has no attribute 'values'
[ERROR][basehttp.log_message()] "GET /selection/11b0a576-5788-4add-8e80-9a8284635f53/ HTTP/1.1" 500 98858
[ERROR][log.log_response()] Internal Server Error: /api/follow/d4ed85e9-b10a-4773-8fb5-ca22e81c72d5/
[ERROR][basehttp.log_message()] "POST /api/follow/d4ed85e9-b10a-4773-8fb5-ca22e81c72d5/ HTTP/1.1" 500 79
[ERROR][log.log_response()] Internal Server Error: /api/bookshelf/books/100/
Traceback (most recent call last):
  File "/usr/local/lib/python3.9/site-packages/django/core/handlers/exception.py", line 47, in inner
    response = get_response(request)
  File "/usr/local/lib/python3.9/site-packages/django/core/handlers/base.py", line 181, in _get_response
    response = wrapped_callback(request, *callback_args, **callback_kwargs)
  File "/usr/local/lib/python3.9/site-packages/django/views/decorators/csrf.py", line 54, in wrapped_view
    return view_func(*args, **kwargs)
  File "/usr/local/lib/python3.9/site-packages/django/views/generic/base.py", line 70, in view
    return self.dispatch(request, *args, **kwargs)
  File "/usr/local/lib/python3.9/site-packages/rest_framework/views.py", line 509, in dispatch
    response = self.handle_exception(exc)
  File "/usr/local/lib/python3.9/site-packages/rest_framework/views.py", line 469, in handle_exception
    self.raise_uncaught_exception(exc)
  File "/usr/local/lib/python3.9/site-packages/rest_framework/views.py", line 480, in raise_uncaught_exception
    raise exc
  File "/usr/local/lib/python3.9/site-packages/rest_framework/views.py", line 506, in dispatch
    response = handler(request, *args, **kwargs)
TypeError: post() got an unexpected keyword argument 'book_id'
[ERROR][basehttp.log_message()] "POST /api/bookshelf/books/100/ HTTP/1.1" 500 87689
[ERROR][log.log_response()] Internal Server Error: /api/bookshelf/books/100/
Traceback (most recent call last):
  File "/usr/local/lib/python3.9/site-packages/django/core/handlers/exception.py", line 47, in inner
    response = get_response(request)
  File "/usr/local/lib/python3.9/site-packages/django/core/handlers/base.py", line 181, in _get_response
    response = wrapped_callback(request, *callback_args, **callback_kwargs)
  File "/usr/local/lib/python3.9/site-packages/django/views/decorators/csrf.py", line 54, in wrapped_view
    return view_func(*args, **kwargs)
  File "/usr/local/lib/python3.9/site-packages/django/views/generic/base.py", line 70, in view
    return self.dispatch(request, *args, **kwargs)
  File "/usr/local/lib/python3.9/site-packages/rest_framework/views.py", line 509, in dispatch
    response = self.handle_exception(exc)
  File "/usr/local/lib/python3.9/site-packages/rest_framework/views.py", line 469, in handle_exception
    self.raise_uncaught_exception(exc)
  File "/usr/local/lib/python3.9/site-packages/rest_framework/views.py", line 480, in raise_uncaught_exception
    raise exc
  File "/usr/local/lib/python3.9/site-packages/rest_framework/views.py", line 506, in dispatch
    response = handler(request, *args, **kwargs)
TypeError: post() got an unexpected keyword argument 'book_id'
[ERROR][basehttp.log_message()] "POST /api/bookshelf/books/100/ HTTP/1.1" 500 87709
